<?xml version="1.0" encoding="utf-8"?>
<robot
  name="biped">
  <link
    name="base_link">
    <inertial>
      <origin
        xyz="-0.000639394470299467 -2.37318373953936E-09 0.0465153734772294"
        rpy="0 0 0" />
      <mass
        value="7.62083335132822" />
      <inertia
        ixx="0.0451858842619121"
        ixy="4.25989822959874E-07"
        ixz="0.00342824655830176"
        iyy="0.0516151579525598"
        iyz="2.11360864436647E-09"
        izz="0.07770577553124" />
    </inertial>
    <visual>
      <origin
        xyz="0 0 0"
        rpy="0 0 0" />
      <geometry>
        <mesh
          filename="package://biped_robot_description/meshes/base_link.STL" />
      </geometry>
      <material
        name="">
        <color
          rgba="0.792156862745098 0.819607843137255 0.933333333333333 1" />
      </material>
    </visual>
    <collision>
      <origin
        xyz="0 0 0"
        rpy="0 0 0" />
      <geometry>
        <mesh
          filename="package://biped_robot_description/meshes/base_link.STL" />
      </geometry>
    </collision>
  </link>
  <link
    name="FR_HIP">
    <inertial>
      <origin
        xyz="-0.04439 -4.3944E-05 -0.063969"
        rpy="0 0 0" />
      <mass
        value="0.35434" />
      <inertia
        ixx="0.00038957"
        ixy="2.8341E-07"
        ixz="4.8692E-05"
        iyy="0.00044213"
        iyz="6.378E-08"
        izz="0.00039356" />
    </inertial>
    <visual>
      <origin
        xyz="0 0 0"
        rpy="0 0 0" />
      <geometry>
        <mesh
          filename="package://biped_robot_description/meshes/FR_HIP.STL" />
      </geometry>
      <material
        name="">
        <color
          rgba="0.69804 0.69804 0.69804 1" />
      </material>
    </visual>
    <collision>
      <origin
        xyz="0 0 0"
        rpy="0 0 0" />
      <geometry>
        <mesh
          filename="package://biped_robot_description/meshes/FR_HIP.STL" />
      </geometry>
    </collision>
  </link>
  <joint
    name="FR_YAW"
    type="revolute">
    <origin
      xyz="0 -0.0700000000000001 -0.0157999999999999"
      rpy="0 0 0" />
    <parent
      link="base_link" />
    <child
      link="FR_HIP" />
        <limit effort="1000" lower="-0.3" upper="0.3" velocity="1000"/>
    <axis
      xyz="0 0 1" />
  </joint>
  <link
    name="FR_SHOULDER">
    <inertial>
      <origin
        xyz="0.0084801 0.022635 -0.00077539"
        rpy="0 0 0" />
      <mass
        value="0.30702" />
      <inertia
        ixx="0.0002067"
        ixy="2.1989E-06"
        ixz="1.1262E-07"
        iyy="0.0003195"
        iyz="4.3332E-06"
        izz="0.00019771" />
    </inertial>
    <visual>
      <origin
        xyz="0 0 0"
        rpy="0 0 0" />
      <geometry>
        <mesh
          filename="package://biped_robot_description/meshes/FR_SHOULDER.STL" />
      </geometry>
      <material
        name="">
        <color
          rgba="1 0 0 1" />
      </material>
    </visual>
    <collision>
      <origin
        xyz="0 0 0"
        rpy="0 0 0" />
      <geometry>
        <mesh
          filename="package://biped_robot_description/meshes/FR_SHOULDER.STL" />
      </geometry>
    </collision>
  </link>
  <joint
    name="FR_HAA"
    type="revolute">
    <origin
      xyz="0 0 -0.073"
      rpy="0 0 0" />
    <parent
      link="FR_HIP" />
    <child
      link="FR_SHOULDER" />
    <axis
      xyz="1 0 0" />
    <limit effort="1000" lower="-0.25" upper="0.25" velocity="1000"/>
  </joint>
  <link
    name="FR_UPPER_LEG">
    <inertial>
      <origin
        xyz="0.00999917539850848 -0.0491846654467433 -0.0389251527043696"
        rpy="0 0 0" />
      <mass
        value="0.459365802658862" />
      <inertia
        ixx="0.00143336057712295"
        ixy="5.12867175943416E-10"
        ixz="6.11565816341328E-08"
        iyy="0.00166768021821664"
        iyz="7.98881842482862E-06"
        izz="0.000320094254580036" />
    </inertial>
    <visual>
      <origin
        xyz="0 0 0"
        rpy="0 0 0" />
      <geometry>
        <mesh
          filename="package://biped_robot_description/meshes/FR_UPPER_LEG.STL" />
      </geometry>
      <material
        name="">
        <color
          rgba="1 0 0 1" />
      </material>
    </visual>
    <collision>
      <origin
        xyz="0 0 0"
        rpy="0 0 0" />
      <geometry>
        <mesh
          filename="package://biped_robot_description/meshes/FR_UPPER_LEG.STL" />
      </geometry>
    </collision>
  </link>
  <joint
    name="FR_HFE"
    type="revolute">
    <origin
      xyz="0 0 0"
      rpy="0 0 0" />
    <parent
      link="FR_SHOULDER" />
    <child
      link="FR_UPPER_LEG" />
    <axis
      xyz="0 1 0" />
      <limit effort="1000" lower="-1.5" upper="1.5" velocity="1000"/>
  </joint>
  <link
    name="FR_LOWER_LEG">
    <inertial>
      <origin
        xyz="8.85333552616378E-06 0.0171411389819433 -0.111259699580943"
        rpy="0 0 0" />
      <mass
        value="0.0911245737715333" />
      <inertia
        ixx="0.000436787158269832"
        ixy="1.05294002111962E-08"
        ixz="1.26662065411541E-08"
        iyy="0.000436804088199172"
        iyz="1.25717901498266E-06"
        izz="1.5386338329274E-05" />
    </inertial>
    <visual>
      <origin
        xyz="0 0 0"
        rpy="0 0 0" />
      <geometry>
        <mesh
          filename="package://biped_robot_description/meshes/FR_LOWER_LEG.STL" />
      </geometry>
      <material
        name="">
        <color
          rgba="0.792156862745098 0.819607843137255 0.933333333333333 1" />
      </material>
    </visual>
    <collision>
      <origin
        xyz="0 0 0"
        rpy="0 0 0" />
      <geometry>
        <mesh
          filename="package://biped_robot_description/meshes/FR_LOWER_LEG.STL" />
      </geometry>
    </collision>
  </link>
  <joint
    name="FR_KFE"
    type="revolute">
    <origin
      xyz="0.01 -0.057399 -0.23429"
      rpy="0 0 0" />
    <parent
      link="FR_UPPER_LEG" />
    <child
      link="FR_LOWER_LEG" />
    <axis
      xyz="0 1 0" />
    <limit effort="1000" lower="0.01" upper="2.2" velocity="1000"/>
  </joint>
  <link
    name="FR_FOOT">
    <inertial>
      <origin
        xyz="-1.50204329982598E-07 -6.55552252759595E-09 -0.0124757843132849"
        rpy="0 0 0" />
      <mass
        value="0.0001" />
      <inertia
        ixx="2.27156674728489E-07"
        ixy="1.8940555569311E-12"
        ixz="4.6640079123731E-12"
        iyy="4.4396263007081E-06"
        iyz="2.90644772891908E-13"
        izz="4.30705177925079E-06" />
    </inertial>
    <visual>
      <origin
        xyz="0 0 0"
        rpy="0 0 0" />
      <geometry>
        <mesh
          filename="package://biped_robot_description/meshes/FR_FOOT.STL" />
      </geometry>
      <material
        name="">
        <color
          rgba="0.792156862745098 0.819607843137255 0.933333333333333 1" />
      </material>
    </visual>
    <collision>
      <origin
        xyz="0 0 0"
        rpy="0 0 0" />
      <geometry>
        <mesh
          filename="package://biped_robot_description/meshes/FR_FOOT.STL" />
      </geometry>
    </collision>
  </link>
  <joint
    name="FR_ANKLE"
    type="revolute">
    <origin
      xyz="0 0.0168 -0.30826"
      rpy="0 0 0" />
    <parent
      link="FR_LOWER_LEG" />
    <child
      link="FR_FOOT" />
    <axis
      xyz="0 1 0" />
    <limit effort="1000" lower="-1.6" upper="1.6" velocity="1000"/>
  </joint>
  <link
    name="FL_HIP">
    <inertial>
      <origin
        xyz="0 0 0"
        rpy="0 0 0" />
      <mass
        value="0.01" />
      <inertia
        ixx="0.001"
        ixy="0"
        ixz="0"
        iyy="0.000001"
        iyz="0"
        izz="0.001" />
    </inertial>
    <visual>
      <origin
        xyz="0 0 0"
        rpy="0 0 0" />
      <geometry>
        <mesh
          filename="package://biped_robot_description/meshes/FL_HIP.STL" />
      </geometry>
      <material
        name="">
        <color
          rgba="1 1 1 1" />
      </material>
    </visual>
    <collision>
      <origin
        xyz="0 0 0"
        rpy="0 0 0" />
      <geometry>
        <mesh
          filename="package://biped_robot_description/meshes/FL_HIP.STL" />
      </geometry>
    </collision>
  </link>
  <joint
    name="FL_YAW"
    type="revolute">
    <origin
      xyz="0 0.07 -0.0158"
      rpy="0 0 0" />
    <parent
      link="base_link" />
    <child
      link="FL_HIP" />
    <axis
      xyz="0 0 1" />
    <limit effort="1000" lower="-0.3" upper="0.3" velocity="1000"/>
  </joint>
  <link
    name="FL_SHOULDER">
    <inertial>
      <origin
        xyz="0.0104369980559036 -0.0218020195475164 0.000775390834242926"
        rpy="0 0 0" />
      <mass
        value="0.307022440099937" />
      <inertia
        ixx="0.000207959995155771"
        ixy="1.20422626794703E-05"
        ixz="4.9308909073799E-07"
        iyy="0.000318246373210611"
        iyz="4.3064865095476E-06"
        izz="0.000197712953246141" />
    </inertial>
    <visual>
      <origin
        xyz="0 0 0"
        rpy="0 0 0" />
      <geometry>
        <mesh
          filename="package://biped_robot_description/meshes/FL_SHOULDER.STL" />
      </geometry>
      <material
        name="">
        <color
          rgba="1 0 0 1" />
      </material>
    </visual>
    <collision>
      <origin
        xyz="0 0 0"
        rpy="0 0 0" />
      <geometry>
        <mesh
          filename="package://biped_robot_description/meshes/FL_SHOULDER.STL" />
      </geometry>
    </collision>
  </link>
  <joint
    name="FL_HAA"
    type="revolute">
    <origin
      xyz="0 0 -0.073"
      rpy="0 0 0" />
    <parent
      link="FL_HIP" />
    <child
      link="FL_SHOULDER" />
    <axis
      xyz="1 0 0" />
    <limit effort="1000" lower="-0.25" upper="0.25" velocity="1000"/>
  </joint>
  <link
    name="FL_UPPER_LEG">
    <inertial>
      <origin
        xyz="0.010000111871374 0.0493505287698992 -0.0385952598840397"
        rpy="0 0 0" />
      <mass
        value="0.459365803346259" />
      <inertia
        ixx="0.00143336057683954"
        ixy="7.736743345379E-10"
        ixz="6.1152529062323E-08"
        iyy="0.00166758735207669"
        iyz="1.37461925754045E-05"
        izz="0.000320187121400746" />
    </inertial>
    <visual>
      <origin
        xyz="0 0 0"
        rpy="0 0 0" />
      <geometry>
        <mesh
          filename="package://biped_robot_description/meshes/FL_UPPER_LEG.STL" />
      </geometry>
      <material
        name="">
        <color
          rgba="0.792156862745098 0.819607843137255 0.933333333333333 1" />
      </material>
    </visual>
    <collision>
      <origin
        xyz="0 0 0"
        rpy="0 0 0" />
      <geometry>
        <mesh
          filename="package://biped_robot_description/meshes/FL_UPPER_LEG.STL" />
      </geometry>
    </collision>
  </link>
  <joint
    name="FL_HFE"
    type="revolute">
    <origin
      xyz="0 0 0"
      rpy="0 0 0" />
    <parent
      link="FL_SHOULDER" />
    <child
      link="FL_UPPER_LEG" />
    <axis
      xyz="0 1 0" />
    <limit effort="1000" lower="-1.5" upper="1.5" velocity="1000"/>
  </joint>
  <link
    name="FL_LOWER_LEG">
    <inertial>
      <origin
        xyz="-8.8533379014686E-06 -0.0171411389745038 -0.111259699612872"
        rpy="0 0 0" />
      <mass
        value="0.0911245737414644" />
      <inertia
        ixx="0.00043678715826298"
        ixy="1.05294010947744E-08"
        ixz="1.26662071930063E-08"
        iyy="0.000436804088197728"
        iyz="1.25717901206459E-06"
        izz="1.53863383236652E-05" />
    </inertial>
    <visual>
      <origin
        xyz="0 0 0"
        rpy="0 0 0" />
      <geometry>
        <mesh
          filename="package://biped_robot_description/meshes/FL_LOWER_LEG.STL" />
      </geometry>
      <material
        name="">
        <color
          rgba="0.792156862745098 0.819607843137255 0.933333333333333 1" />
      </material>
    </visual>
    <collision>
      <origin
        xyz="0 0 0"
        rpy="0 0 0" />
      <geometry>
        <mesh
          filename="package://biped_robot_description/meshes/FL_LOWER_LEG.STL" />
      </geometry>
    </collision>
  </link>
  <joint
    name="FL_KFE"
    type="revolute">
    <origin
      xyz="0.0099993 0.0584 -0.23393"
      rpy="0 0 0" />
    <parent
      link="FL_UPPER_LEG" />
    <child
      link="FL_LOWER_LEG" />
    <axis
      xyz="0 1 0" />
    <limit effort="1000" lower="0.01" upper="2.2" velocity="1000"/>
  </joint>
  <link
    name="FL_FOOT">
    <inertial>
      <origin
        xyz="1.50204329408404E-07 6.55552259698489E-09 -0.0124757843132849"
        rpy="0 0 0" />
      <mass
        value="0.0001" />
      <inertia
        ixx="2.27156674728491E-07"
        ixy="1.89405555797E-12"
        ixz="4.66400790097924E-12"
        iyy="4.43962630070825E-06"
        iyz="2.90644772485E-13"
        izz="4.30705177925094E-06" />
    </inertial>
    <visual>
      <origin
        xyz="0 0 0"
        rpy="0 0 0" />
      <geometry>
        <mesh
          filename="package://biped_robot_description/meshes/FL_FOOT.STL" />
      </geometry>
      <material
        name="">
        <color
          rgba="0.792156862745098 0.819607843137255 0.933333333333333 1" />
      </material>
    </visual>
    <collision>
      <origin
        xyz="0 0 0"
        rpy="0 0 0" />
      <geometry>
        <mesh
          filename="package://biped_robot_description/meshes/FL_FOOT.STL" />
      </geometry>
    </collision>
  </link>
  <joint
    name="FL_ANKLE"
    type="revolute">
    <origin
      xyz="0 -0.0168 -0.30826"
      rpy="0 0 0" />
    <parent
      link="FL_LOWER_LEG" />
    <child
      link="FL_FOOT" />
    <axis
      xyz="0 1 0" />
    <limit effort="1000" lower="-1.6" upper="1.6" velocity="1000"/>
  </joint>
</robot>