<mujoco model="biped">
  <compiler angle="radian" meshdir="../meshes/"/>
  <size njmax="10000" nconmax="10000"/>
  <option integrator="RK4"/>
  <default/>
  <asset>
    <mesh name="base_link" file="base_link.STL"/>
    <mesh name="R_HIP" file="R_HIP.STL"/>
    <mesh name="R_SHOULDER" file="R_SHOULDER.STL"/>
    <mesh name="R_UPPER_LEG" file="R_UPPER_LEG.STL"/>
    <mesh name="R_LOWER_LEG" file="R_LOWER_LEG.STL"/>
    <mesh name="R_FOOT" file="R_FOOT.STL"/>
    <mesh name="L_HIP" file="L_HIP.STL"/>
    <mesh name="L_SHOULDER" file="L_SHOULDER.STL"/>
    <mesh name="L_UPPER_LEG" file="L_UPPER_LEG.STL"/>
    <mesh name="L_LOWER_LEG" file="L_LOWER_LEG.STL"/>
    <mesh name="L_FOOT" file="L_FOOT.STL"/>

    <texture type="skybox" builtin="gradient" width="128" height="128" rgb1=".4 .6 .8" rgb2="0 0 0"/>
    
    <hfield name="hill" nrow="400" ncol="400" size="8 8 1 1"/>

    <!-- <hfield name="hill" size = "4 4 0.2 0.5" file="../terrains/test_hills.png"/> -->

    <texture builtin="checker" height="100" name="texplane" rgb1="0.14 0.31 0.27" rgb2="0.47 0.63 0.6" type="2d" width="100"/>
    <material name="MatPlane" reflectance="0.5" shininess="1" specular="1" texrepeat="60 60"  texture="texplane"/>

  </asset>

  <equality>
		<weld body1="base_link" solimp="0.2 0.1 1" solref="0.06 1"></weld>
	</equality>

  <sensor>
      <gyro name="gyro" site="imu_location" />
      <accelerometer name="accelerometer" site="imu_location" />
  </sensor>


  <worldbody>
    
    <light cutoff="100" diffuse="1 1 1" dir="-0 0 -1.3" directional="true" exponent="1" pos="0 0 1.3" specular=".1 .1 .1"/>
    <geom name="floor" friction="1 .1 .1" condim="3" material="MatPlane" pos="0 0 0" rgba="0.8 0.9 0.8 1" size="40 40 0.01" type="plane"/>


    <body name="base_link" pos="0.0 0.0 1.0">
      <inertial pos="-0.04487 -0.003300 0.071612" quat="1. 0. 0. 0." mass="2.123284" diaginertia="0.0062845 0.002920 0.0075164" />
      <geom name="base_link" type="mesh" contype="2" rgba="1 1 1 1" mesh="base_link"/>
      <joint armature="0" damping="0" limited="false" name="root" pos="0 0 0" stiffness="0" type="free"/>
      <site name="imu_location" pos="0 0 0" euler="-180 0 0" size="0.01" type="sphere" rgba="1 0 0 1"/>

      
      <body name="L_HIP" pos="0 0.07 -0.005">
        <inertial pos="0.0219446 2.88517e-09 -0.0303917" quat="0.366769 0.60455 0.60455 0.366769" mass="0.0629568" diaginertia="0.000152966 0.000140349 2.75872e-05"/>
        <joint name="L_YAW" pos="0 0 0" axis="0 0 1" limited="true" range="-0.3 0.3"/>
        <geom name="L_HIP" type="mesh" contype="2" rgba="1 1 1 1" mesh="L_HIP"/>
        
        <body name="L_SHOULDER" pos="0.0069 0 -0.081">
          <inertial pos="-0.0382844 -0.0118964 0.00204772" quat="0.99855 0.0172952 -0.0163405 0.0482982" mass="0.588644" diaginertia="0.00052221 0.000511105 0.000391968"/>
          <joint name="L_HAA" pos="0 0 0" axis="1 0 0" limited="true" range="-0.25 0.25"/>
          <geom name="L_SHOULDER" type="mesh" contype="2" rgba="1 0 0 1" mesh="L_SHOULDER"/>

          <body name="L_UPPER_LEG" pos="0 0 0">
            <inertial pos="-0.000328851 0.0508507 -0.0528924" quat="0.708239 0.00455438 -0.00524832 0.705938" mass="0.544558" diaginertia="0.00134762 0.00110961 0.000336902"/>
            <joint name="L_HFE" pos="0 0 0" axis="0 1 0" limited="true" range="-1.5 1.5"/>
            <geom name="L_UPPER_LEG" type="mesh" contype="2"  rgba="1 0 0 1" mesh="L_UPPER_LEG"/>
            
            <body name="L_LOWER_LEG" pos="0 0.0589 -0.23405">
              <inertial pos="0.0167444 -0.010503 -0.111301" quat="0.61399 -0.000936386 0.00122879 0.789312" mass="0.0923619" diaginertia="0.000437226 0.000437181 1.55724e-05"/>
              <joint name="L_KFE" pos="0 0 0" axis="0 1 0" limited="true" range="-2.2 -0.1"/>
              <geom name="L_LOWER_LEG" type="mesh" contype="2" rgba="0.792157 0.819608 0.933333 1" mesh="L_LOWER_LEG"/>
              
              <body name="L_FOOT" pos="0 -0.0168 -0.30826">
                <inertial pos="3.02322e-05 -2.36197e-08 -0.0242543" quat="0 0.707065 0 0.707149" mass="0.0313407" diaginertia="3.39896e-05 3.35525e-05 1.53506e-06"/>
                <joint name="L_ANKLE" pos="0 0 0" axis="0 1 0" limited="true" range="-0.7 0.7"/>
                <geom name="L_FOOT" friction="1. 0.3 0.3" size="0.015 0.05" pos="0 0 -0.01" quat="0.710914 0 0.703279 0"  type="capsule" rgba="0.8 0.8 0.8 1"/>

              </body>
            </body>
          </body>
        </body>
      </body>


      <body name="R_HIP" pos="0 -0.07 -0.005">
        <inertial pos="0.0219446 2.88517e-09 -0.0303917" quat="0.366769 0.60455 0.60455 0.366769" mass="0.0629568" diaginertia="0.000152966 0.000140349 2.75872e-05"/>
        <joint name="R_YAW" pos="0 0 0" axis="0 0 1" limited="true" range="-0.3 0.3"/>
        <geom name="R_HIP" type="mesh" contype="2" rgba="0.69804 0.69804 0.69804 1" mesh="R_HIP"/>
        
        <body name="R_SHOULDER" pos="0.0069 0 -0.081">
          <inertial pos="-0.0382844 0.0118964 0.00123887" quat="0.999072 0.0188564 -0.0150807 -0.0356764" mass="0.588644" diaginertia="0.000522165 0.000511155 0.000391964"/>
          <joint name="R_HAA" pos="0 0 0" axis="1 0 0" limited="true" range="-0.25 0.25"/>
          <geom name="R_SHOULDER" type="mesh" contype="2" rgba="1 0 0 1" mesh="R_SHOULDER"/>
          
          <body name="R_UPPER_LEG" pos="0 0 0">
            <inertial pos="0.000674123 -0.0518216 -0.040538" quat="0.708424 -0.00163377 0.0024851 0.705781" mass="0.512204" diaginertia="0.00132251 0.00110712 0.000298067"/>
            <joint name="R_HFE" pos="0 0 0" axis="0 1 0" limited="true" range="-1.5 1.5"/>
            <geom name="R_UPPER_LEG" type="mesh" contype="2" rgba="1 0 0 1" mesh="R_UPPER_LEG"/>
            
            <body name="R_LOWER_LEG" pos="0 -0.0584 -0.23405">
              <inertial pos="-0.14942 0.0171035 -0.165665" quat="0.61399 0.000936386 -0.00122879 0.789312" mass="0.0923619" diaginertia="0.000437226 0.000437181 1.55724e-05"/>
              <joint name="R_KFE" pos="0 0 0" axis="0 1 0" limited="true" range="-2.2 -0.1"/>
              <geom name="R_LOWER_LEG" type="mesh" contype="2" rgba="0.792157 0.819608 0.933333 1" mesh="R_LOWER_LEG"/>
              
              <body name="R_FOOT" pos="0 0.0168 -0.30826">
                <inertial pos="-3.02322e-05 2.36197e-08 -0.0242543" quat="0 0.707149 0 0.707065" mass="0.0313407" diaginertia="3.39896e-05 3.35525e-05 1.53506e-06"/>
                <joint name="R_ANKLE" pos="0 0 0" axis="0 1 0" limited="true" range="-0.7 0.7"/>
                <geom name="R_FOOT" friction="1. 0.3 0.3" size="0.015 0.05" pos="0 0 -0.01" quat="0.710914 0 0.703279 0"  type="capsule" rgba="0.8 0.8 0.8 1"/>
              </body>
            </body>
          </body>
        </body>
      </body>
      
    </body>
  </worldbody>


      <actuator>

        <motor gear="1"  joint="L_YAW" name="L_YAW"/>
            <velocity gear="1" joint="L_YAW" name="L_YAW_VEL" kv="0.5" />

        <motor gear="1"  joint="L_HAA" name="L_HAA"/>
            <velocity gear="1" joint="L_HAA" name="L_HAA_VEL" kv="0.5" />

        <motor gear="1"  joint="L_HFE" name="L_HFE"/>
            <velocity gear="1" joint="L_HFE" name="L_HFE_VEL" kv="0.5" />

        <motor gear="1"  joint="L_KFE" name="L_KFE"/>
            <velocity gear="1" joint="L_KFE" name="L_KFE_VEL" kv="0.35 " />

        <motor gear="1"  joint="L_ANKLE" name="L_ANKLE"/>
            <velocity gear="1" joint="L_ANKLE" name="L_ANKLE_VEL" kv="0.005" />

        <motor gear="1"  joint="R_YAW" name="R_YAW"/>
            <velocity gear="1" joint="R_YAW" name="R_YAW_VEL" kv="0.5" />

        <motor gear="1"  joint="R_HAA" name="R_HAA"/>
            <velocity gear="1" joint="R_HAA" name="R_HAA_VEL" kv="0.5" />

        <motor gear="1"  joint="R_HFE" name="R_HFE"/>
            <velocity gear="1" joint="R_HFE" name="R_HFE_VEL" kv="0.5" />

        <motor gear="1"  joint="R_KFE" name="R_KFE"/>
            <velocity gear="1" joint="R_KFE" name="R_KFE_VEL" kv="0.35 " />

        <motor gear="1"  joint="R_ANKLE" name="R_ANKLE"/>
            <velocity gear="1" joint="R_ANKLE" name="R_ANKLE_VEL" kv="0.005" />
    </actuator>


</mujoco>
