<?xml version="1.0" encoding="utf-8"?>
<robot
  name="biped">

  <mujoco>
        <compiler 
        meshdir="../meshes/" 
        balanceinertia="false" 
        discardvisual="false" />
  </mujoco>

  <!-- Imu -->
  <link name="imu">
    <visual>
      <origin xyz="0 0 0" rpy="0 0 0"/>
      <geometry>
      <box size="0.03 0.03 0.01"/>
      </geometry>
    </visual>

    <inertial>
      <mass value="0.01" />
      <origin xyz="0 0 0" rpy="0 0 0"/>
      <inertia ixx="1e-5" ixy="0" ixz="0" iyy="1e-5" iyz="0" izz="1e-5" />
    </inertial>
  </link>

  <joint name="imu_joint" type="fixed">
      <origin xyz="0 0 0" rpy="-3.141592 0 0"/>
      <parent link="base_link"/>
      <child link="imu"/>
  </joint>

  <link
    name="base_link">
    <inertial>
      <origin
        xyz="-0.0448709592682471 0.0 0.0716121411080205"
        rpy="0 0 0" />
      <mass
        value="3.213" />
      <inertia
        ixx="0.023493"
        ixy="0.0"
        ixz="0.0"
        iyy="0.027733"
        iyz="0.0"
        izz="0.03757" />
    </inertial>
    <visual>
      <origin
        xyz="0 0 0"
        rpy="0 0 0" />
      <geometry>
        <mesh
          filename="package://biped_robot_description/meshes/base_link.STL" />
      </geometry>
      <material
        name="">
        <color
          rgba="0.752941176470588 0.752941176470588 0.752941176470588 1" />
      </material>
    </visual>
    <collision>
      <origin
        xyz="0 0 0"
        rpy="0 0 0" />
      <geometry>
        <mesh
          filename="package://biped_robot_description/meshes/base_link.STL" />
      </geometry>
    </collision>
  </link>
  <link
    name="R_HIP">
 <inertial>
      <origin
        xyz="0.0219446 0.0 -0.0303917"
        rpy="0 0 0" />
      <mass
        value="0.0629568480892822" />
      <inertia
        ixx="0.0000516473"
        ixy="-3.57588662405679E-11"
        ixz="4.61970829805285E-05"
        iyy="0.00015296"
        iyz="6.07063377437121E-12"
        izz="0.0001162" />
    </inertial>
    <visual>
      <origin
        xyz="0 0 0"
        rpy="0 0 0" />
      <geometry>
        <mesh
          filename="package://biped_robot_description/meshes/R_HIP.STL" />
      </geometry>
      <material
        name="">
        <color
          rgba="0.698039215686274 0.698039215686274 0.698039215686274 1.0" />
      </material>
    </visual>
    <collision>
      <origin
        xyz="0 0 0"
        rpy="0 0 0" />
      <geometry>
        <mesh
          filename="package://biped_robot_description/meshes/R_HIP.STL" />
      </geometry>
    </collision>
  </link>
  <joint
    name="R_YAW"
    type="revolute">
    <origin
      xyz="0 -0.07 -0.005"
      rpy="0 0 0" />
    <parent
      link="base_link" />
    <child
      link="R_HIP" />
    <axis
      xyz="0 0 1" />
    <limit
      lower="-0.3"
      upper="0.3"
      effort="1000"
      velocity="1000" />
  </joint>
  <link
    name="R_SHOULDER">
      <inertial>
      <origin
        xyz="-0.038284 0.0118964 0.00204771"
        rpy="0 0 0" />
      <mass
        value="1.009" />
      <inertia
        ixx="0.00052198"
        ixy="0.0"
        ixz="0.0"
        iyy="0.000511"
        iyz="0.0"
        izz="0.00039225" />
    </inertial>
    <visual>
      <origin
        xyz="0 0 0"
        rpy="0 0 0" />
      <geometry>
        <mesh
          filename="package://biped_robot_description/meshes/R_SHOULDER.STL" />
      </geometry>
      <material
        name="">
        <color
          rgba="0.698039215686274 0.698039215686274 0.698039215686274 1" />
      </material>
    </visual>
    <collision>
      <origin
        xyz="0 0 0"
        rpy="0 0 0" />
      <geometry>
        <mesh
          filename="package://biped_robot_description/meshes/R_SHOULDER.STL" />
      </geometry>
    </collision>
  </link>
  <joint
    name="R_HAA"
    type="revolute">
    <origin
      xyz="0.0069 0 -0.081"
      rpy="0 0 0" />
    <parent
      link="R_HIP" />
    <child
      link="R_SHOULDER" />
    <axis
      xyz="1 0 0" />
    <limit
      lower="-0.25"
      upper="0.25"
      effort="1000"
      velocity="1000" />
  </joint>
  <link
    name="R_UPPER_LEG">
    <inertial>
      <origin
        xyz="-0.00032 0.05085 -0.05289"
        rpy="0 0 0" />
      <mass
        value="0.800" />
      <inertia
        ixx="0.00110"
        ixy="0.0"
        ixz="0.0"
        iyy="0.001347"
        iyz="1.400836E-05"
        izz="0.00033709" />
    </inertial>
    <visual>
      <origin
        xyz="0 0 0"
        rpy="0 0 0" />
      <geometry>
        <mesh
          filename="package://biped_robot_description/meshes/R_UPPER_LEG.STL" />
      </geometry>
      <material
        name="">
        <color
          rgba="0.698039215686274 0.698039215686274 0.698039215686274 1" />
      </material>
    </visual>
    <collision>
      <origin
        xyz="0 0 0"
        rpy="0 0 0" />
      <geometry>
        <mesh
          filename="package://biped_robot_description/meshes/R_UPPER_LEG.STL" />
      </geometry>
    </collision>
  </link>
  <joint
    name="R_HFE"
    type="revolute">
    <origin
      xyz="0 0 0"
      rpy="0 0 0" />
    <parent
      link="R_SHOULDER" />
    <child
      link="R_UPPER_LEG" />
    <axis
      xyz="0 1 0" />
    <limit
      lower="-1.5"
      upper="1.5"
      effort="1000"
      velocity="1000" />
  </joint>
  <link
    name="R_LOWER_LEG">
    <inertial>
      <origin
        xyz="0.0 0.0176 -0.1117"
        rpy="0 0 0" />
      <mass
        value="0.09236" />
      <inertia
        ixx="0.00043718"
        ixy="0.0"
        ixz="0.0"
        iyy="0.000437218"
        iyz="-1.302748E-06"
        izz="1.557642E-05" />
    </inertial>
    <visual>
      <origin
        xyz="0 0 0"
        rpy="0 0 0" />
      <geometry>
        <mesh
          filename="package://biped_robot_description/meshes/R_LOWER_LEG.STL" />
      </geometry>
      <material
        name="">
        <color
          rgba="1 1 1 1" />
      </material>
    </visual>
    <collision>
      <origin
        xyz="0 0 0"
        rpy="0 0 0" />
      <geometry>
        <mesh
          filename="package://biped_robot_description/meshes/R_LOWER_LEG.STL" />
      </geometry>
    </collision>
  </link>
  <joint
    name="R_KFE"
    type="revolute">
    <origin
      xyz="0 -0.0589 -0.23405"
      rpy="0 0 0" />
    <parent
      link="R_UPPER_LEG" />
    <child
      link="R_LOWER_LEG" />
    <axis
      xyz="0 1 0" />
    <limit
      lower="-2.2"
      upper="-0.1"
      effort="1000"
      velocity="1000" />
  </joint>
  <link
    name="R_FOOT">
    <inertial>
      <origin
        xyz="-3.02321900789403E-05 2.36197425507179E-08 -0.0242542849058649"
        rpy="0 0 0" />
      <mass
        value="0.0313407448211579" />
      <inertia
        ixx="1.53505900340827E-06"
        ixy="3.21655852895147E-11"
        ixz="3.87851927561161E-09"
        iyy="3.35525061902405E-05"
        iyz="-1.30436886653959E-12"
        izz="3.3989583673629E-05" />
    </inertial>
    <visual>
      <origin
        xyz="0 0 0"
        rpy="0 0 0" />
      <geometry>
        <mesh
          filename="package://biped_robot_description/meshes/R_FOOT.STL" />
      </geometry>
      <material
        name="">
        <color
          rgba="0.698039215686274 0.698039215686274 0.698039215686274 1" />
      </material>
    </visual>
    <collision>
      <origin
        xyz="0 0 0"
        rpy="0 0 0" />
      <geometry>
        <mesh
          filename="package://biped_robot_description/meshes/R_FOOT.STL" />
      </geometry>
    </collision>
  </link>
  <joint
    name="R_ANKLE"
    type="revolute">
    <origin
      xyz="0 0.0173 -0.30826"
      rpy="0 0 0" />
    <parent
      link="R_LOWER_LEG" />
    <child
      link="R_FOOT" />
    <axis
      xyz="0 1 0" />
    <limit
      lower="-1.6"
      upper="1.6"
      effort="1000"
      velocity="1000" />
  </joint>

  <link name="R_FOOT_CONTACT"></link>
  <joint
    name="R_FOOT_CONTACT_JOINT"
    type="fixed">
    <origin
      xyz="0.0 0.0173 -0.30826"
      rpy="0 0 0" />
    <parent link="R_LOWER_LEG" />
    <child link="R_FOOT_CONTACT" />
  </joint>


  <link
    name="L_HIP">
    <inertial>
      <origin
        xyz="0.0219446 0.0 -0.0303917"
        rpy="0 0 0" />
      <mass
        value="0.0629568480892822" />
      <inertia
        ixx="0.0000516473"
        ixy="-3.57588662405679E-11"
        ixz="4.61970829805285E-05"
        iyy="0.00015296"
        iyz="6.07063377437121E-12"
        izz="0.0001162" />
    </inertial>
    <visual>
      <origin
        xyz="0 0 0"
        rpy="0 0 0" />
      <geometry>
        <mesh
          filename="package://biped_robot_description/meshes/L_HIP.STL" />
      </geometry>
      <material
        name="">
        <color
          rgba="0.698039215686274 0.698039215686274 0.698039215686274 1.0" />
      </material>
    </visual>
    <collision>
      <origin
        xyz="0 0 0"
        rpy="0 0 0" />
      <geometry>
        <mesh
          filename="package://biped_robot_description/meshes/L_HIP.STL" />
      </geometry>
    </collision>
  </link>
  <joint
    name="L_YAW"
    type="revolute">
    <origin
      xyz="0 0.07 -0.005"
      rpy="0 0 0" />
    <parent
      link="base_link" />
    <child
      link="L_HIP" />
    <axis
      xyz="0 0 1" />
    <limit
      lower="-0.3"
      upper="0.3"
      effort="1000"
      velocity="1000" />
  </joint>
  <link
    name="L_SHOULDER">
    <inertial>
      <origin
        xyz="-0.038284 -0.0118964 0.00204771"
        rpy="0 0 0" />
      <mass
        value="1.009" />
      <inertia
        ixx="0.00052198"
        ixy="0.0"
        ixz="0.0"
        iyy="0.000511"
        iyz="0.0"
        izz="0.00039225" />
    </inertial>
    <visual>
      <origin
        xyz="0 0 0"
        rpy="0 0 0" />
      <geometry>
        <mesh
          filename="package://biped_robot_description/meshes/L_SHOULDER.STL" />
      </geometry>
      <material
        name="">
        <color
          rgba="0.698039215686274 0.698039215686274 0.698039215686274 1" />
      </material>
    </visual>
    <collision>
      <origin
        xyz="0 0 0"
        rpy="0 0 0" />
      <geometry>
        <mesh
          filename="package://biped_robot_description/meshes/L_SHOULDER.STL" />
      </geometry>
    </collision>
  </link>
  <joint
    name="L_HAA"
    type="revolute">
    <origin
      xyz="0.0069 0 -0.081"
      rpy="0 0 0" />
    <parent
      link="L_HIP" />
    <child
      link="L_SHOULDER" />
    <axis
      xyz="1 0 0" />
    <limit
      lower="-0.25"
      upper="0.25"
      effort="1000"
      velocity="1000" />
  </joint>
  <link
    name="L_UPPER_LEG">
    <inertial>
      <origin
        xyz="-0.00032 -0.05085 -0.05289"
        rpy="0 0 0" />
      <mass
        value="0.800" />
      <inertia
        ixx="0.00110"
        ixy="0.0"
        ixz="0.0"
        iyy="0.001347"
        iyz="1.400836E-05"
        izz="0.00033709" />
    </inertial>
    <visual>
      <origin
        xyz="0 0 0"
        rpy="0 0 0" />
      <geometry>
        <mesh
          filename="package://biped_robot_description/meshes/L_UPPER_LEG.STL" />
      </geometry>
      <material
        name="">
        <color
          rgba="0.898039215686275 0.917647058823529 0.929411764705882 1" />
      </material>
    </visual>
    <collision>
      <origin
        xyz="0 0 0"
        rpy="0 0 0" />
      <geometry>
        <mesh
          filename="package://biped_robot_description/meshes/L_UPPER_LEG.STL" />
      </geometry>
    </collision>
  </link>
  <joint
    name="L_HFE"
    type="revolute">
    <origin
      xyz="0 0 0"
      rpy="0 0 0" />
    <parent
      link="L_SHOULDER" />
    <child
      link="L_UPPER_LEG" />
    <axis
      xyz="0 1 0" />
    <limit
      lower="-1.5"
      upper="1.5"
      effort="1000"
      velocity="1000" />
  </joint>
  <link
    name="L_LOWER_LEG">
    <inertial>
      <origin
        xyz="0.0 -0.0176 -0.1117"
        rpy="0 0 0" />
      <mass
        value="0.09236" />
      <inertia
        ixx="0.00043718"
        ixy="0.0"
        ixz="0.0"
        iyy="0.000437218"
        iyz="-1.302748E-06"
        izz="1.557642E-05" />
    </inertial>
    <visual>
      <origin
        xyz="0 0 0"
        rpy="0 0 0" />
      <geometry>
        <mesh
          filename="package://biped_robot_description/meshes/L_LOWER_LEG.STL" />
      </geometry>
      <material
        name="">
        <color
          rgba="1 1 1 1" />
      </material>
    </visual>
    <collision>
      <origin
        xyz="0 0 0"
        rpy="0 0 0" />
      <geometry>
        <mesh
          filename="package://biped_robot_description/meshes/L_LOWER_LEG.STL" />
      </geometry>
    </collision>
  </link>
  <joint
    name="L_KFE"
    type="revolute">
    <origin
      xyz="0 0.0589 -0.23405"
      rpy="0 0 0" />
    <parent
      link="L_UPPER_LEG" />
    <child
      link="L_LOWER_LEG" />
    <axis
      xyz="0 1 0" />
    <limit
      lower="-2.2"
      upper="-0.1"
      effort="1000"
      velocity="1000" />
  </joint>
  <link
    name="L_FOOT">
    <inertial>
      <origin
        xyz="3.02321900789151E-05 -2.36197425507179E-08 -0.0242542849058648"
        rpy="0 0 0" />
      <mass
        value="0.0313407448211584" />
      <inertia
        ixx="1.53505900340824E-06"
        ixy="3.21655852743254E-11"
        ixz="-3.8785192756099E-09"
        iyy="3.35525061902412E-05"
        iyz="1.30436886701902E-12"
        izz="3.39895836736297E-05" />
    </inertial>
    <visual>
      <origin
        xyz="0 0 0"
        rpy="0 0 0" />
      <geometry>
        <mesh
          filename="package://biped_robot_description/meshes/L_FOOT.STL" />
      </geometry>
      <material
        name="">
        <color
          rgba="0.698039215686274 0.698039215686274 0.698039215686274 1" />
      </material>
    </visual>
    <collision>
      <origin
        xyz="0 0 0"
        rpy="0 0 0" />
      <geometry>
        <mesh
          filename="package://biped_robot_description/meshes/L_FOOT.STL" />
      </geometry>
    </collision>
  </link>
  <joint
    name="L_ANKLE"
    type="revolute">
    <origin
      xyz="0 -0.0173 -0.30826"
      rpy="0 0 0" />
    <parent
      link="L_LOWER_LEG" />
    <child
      link="L_FOOT" />
    <axis
      xyz="0 1 0" />
    <limit
      lower="-1.6"
      upper="1.6"
      effort="1000"
      velocity="1000" />
  </joint>

  <link name="L_FOOT_CONTACT"></link>
  <joint
    name="L_FOOT_CONTACT_JOINT"
    type="fixed">
    <origin
      xyz="0.0 -0.0173 -0.30826"
      rpy="0 0 0" />
    <parent link="L_LOWER_LEG" />
    <child link="L_FOOT_CONTACT" />
  </joint>

</robot>