<mujoco model="biped">
  <compiler angle="radian" meshdir="../meshes/" autolimits="true"/>
  <option integrator="RK4"/>
  <default/>
  <asset>

    <mesh name="L_SHOULDER" file="L_SHOULDER.STL"/>
    <mesh name="L_UPPER_LEG" file="L_UPPER_LEG.STL"/>
    <mesh name="L_LOWER_LEG" file="L_LOWER_LEG.STL"/>
    <mesh name="L_FOOT" file="L_FOOT.STL"/>

    <texture builtin="checker" height="100" name="texplane" rgb1="0.14 0.31 0.27" rgb2="0.47 0.63 0.6" type="2d" width="100"/>
    <material name="MatPlane" reflectance="0.5" shininess="1" specular="1" texrepeat="60 60"  texture="texplane"/>

  </asset>

  <equality>
		<weld body1="L_SHOULDER" solimp="1.0 1.0 1.0" solref="0.06 1"></weld>
	</equality>

  <worldbody>
    <light cutoff="100" diffuse="1 1 1" dir="-0 0 -1.3" directional="true" exponent="1" pos="0 0 1.3" specular=".1 .1 .1"/>
    <geom name="floor" friction="1 .1 .1" condim="3" material="MatPlane" pos="0 0 0" rgba="0.8 0.9 0.8 1" size="40 40 0.01" type="plane"/>

    <body name="L_SHOULDER" pos="0.0069 0 -0.081">
      <inertial pos="-0.0382844 -0.0118964 0.0020477" quat="1. 0. 0. 0."  mass="1.009" diaginertia="0.00052198 0.000511 0.00039225"/>
      <joint name="L_HAA" pos="0 0 0" axis="1 0 0" limited="true" range="-0.25 0.25"/>
      <geom name="L_SHOULDER" type="mesh" contype="2" rgba="1 0 0 1" mesh="L_SHOULDER"/>

      <body name="L_UPPER_LEG" pos="0 0 1.0">
        <inertial pos="-0.00032 -0.05085 -0.05289" quat="1. 0. 0. 0." mass="0.800" diaginertia="0.00110 0.001347 0.00033709"/>
        <joint name="L_HFE" pos="0 0 0" axis="0 1 0" limited="true" range="-1.5 1.5"/>
        <geom name="L_UPPER_LEG" type="mesh" contype="2"  rgba="1 0 0 1" mesh="L_UPPER_LEG"/>
        
        <body name="L_LOWER_LEG" pos="0 0.0589 -0.23405">
          <inertial pos="0.0 -0.0176 -0.1117" quat="1. 0. 0. 0." mass="0.0923619" diaginertia="0.000437226 0.000437181 1.55724e-05"/>
          <joint name="L_KFE" pos="0 0 0" axis="0 1 0" limited="true" range="-2.2 -0.1"/>
          <geom name="L_LOWER_LEG" type="mesh" contype="2" rgba="0.792157 0.819608 0.933333 1" mesh="L_LOWER_LEG"/>
          
          <body name="L_FOOT" pos="0 -0.0173 -0.30826">
            <inertial pos="3.02322e-05 -2.36197e-08 -0.0242543" quat="0.710914 0 0.703279 0" mass="0.03134" diaginertia="3.39896e-05 3.35525e-05 1.53506e-06"/>
            <joint name="L_ANKLE" pos="0 0 0" axis="0 1 0" limited="true" range="-0.7 0.7"/>
            <geom name="L_FOOT" friction="1. 0.3 0.3" size="0.015 0.05" pos="0 0 -0.01" quat="0.710914 0 0.703279 0"  type="capsule" rgba="0.8 0.8 0.8 1"/>

          </body>

        </body>
     
      </body>

    </body>

  </worldbody>

  <actuator>
      <motor gear="1"  joint="L_HAA" name="L_HAA"/>
        <velocity gear="1" joint="L_HAA" name="L_HAA_VEL" kv="3.18" />
      <motor gear="1"  joint="L_HFE" name="L_HFE"/>
          <velocity gear="1" joint="L_HFE" name="L_HFE_VEL" kv="3.18" />
      <motor gear="1"  joint="L_KFE" name="L_KFE"/>
          <velocity gear="1" joint="L_KFE" name="L_KFE_VEL" kv="0.95" />
      <motor gear="1"  joint="L_ANKLE" name="L_ANKLE"/>
          <velocity gear="1" joint="L_ANKLE" name="L_ANKLE_VEL" kv="0.005" />
  </actuator>
</mujoco>
