<?xml version="1.0" encoding="utf-8"?>
<robot
      name="biped">

  <mujoco>
        <compiler 
        meshdir="../meshes_no_yaw/" 
        balanceinertia="false" 
        discardvisual="false" />
  </mujoco>

  <!-- Imu -->
  <link name="imu">
    <visual>
      <origin xyz="0 0 0" rpy="0 0 0"/>
      <geometry>
      <box size="0.03 0.03 0.01"/>
      </geometry>
    </visual>

    <inertial>
      <mass value="0.01" />
      <origin xyz="0 0 0" rpy="0 0 0"/>
      <inertia ixx="1e-5" ixy="0" ixz="0" iyy="1e-5" iyz="0" izz="1e-5" />
    </inertial>
  </link>

  <joint name="imu_joint" type="fixed">
      <origin xyz="0 0 0" rpy="-3.141592 0 0"/>
      <parent link="base_link"/>
      <child link="imu"/>
  </joint>  

  <link
    name="base_link">
    <inertial>
      <origin
        xyz="-0.025692 -0.003004 0.025162"
        rpy="0 0 0" />
      <mass
        value="4.8" />
      <inertia
        ixx="0.056665"
        ixy="0"
        ixz="0"
        iyy="0.046196"
        iyz="0"
        izz="0.042241" />
    </inertial>
    <visual>
      <origin
        xyz="0 0 0"
        rpy="0 0 0" />
      <geometry>
        <mesh
          filename="package://biped_robot_description/meshes_no_yaw/base_link.STL" />
      </geometry>
      <material
        name="">
        <color
          rgba="1 0 0 1" />
      </material>
    </visual>
    <collision>
      <origin
        xyz="0 0 0"
        rpy="0 0 0" />
      <geometry>
        <mesh
          filename="package://biped_robot_description/meshes_no_yaw/base_link.STL" />
      </geometry>
    </collision>
  </link>
  <link
    name="R_SHOULDER">
    <inertial>
      <origin
        xyz="-0.00039 0.022865 -0.000966"
        rpy="0 0 0" />
      <mass
        value="0.52963" />
      <inertia
        ixx="0.000368"
        ixy="0"
        ixz="0"
        iyy="0.000691"
        iyz="0"
        izz="0.000491" />
    </inertial>
    <visual>
      <origin
        xyz="0 0 0"
        rpy="0 0 0" />
      <geometry>
        <mesh
          filename="package://biped_robot_description/meshes_no_yaw/R_SHOULDER.STL" />
      </geometry>
      <material
        name="">
        <color
          rgba="1 1 1 1" />
      </material>
    </visual>
    <collision>
      <origin
        xyz="0 0 0"
        rpy="0 0 0" />
      <geometry>
        <mesh
          filename="package://biped_robot_description/meshes_no_yaw/R_SHOULDER.STL" />
      </geometry>
    </collision>
  </link>
  <joint
    name="R_HAA"
    type="revolute">
    <origin
      xyz="0.005 -0.07 -0.091"
      rpy="0 0 0" />
    <parent
      link="base_link" />
    <child
      link="R_SHOULDER" />
    <axis
      xyz="1 0 0" />
    <limit
      lower="-0.25"
      upper="0.25"
      effort="20"
      velocity="20" />
  </joint>
  <link
    name="R_UPPER_LEG">
    <inertial>
      <origin
        xyz="-2.3E-05 -0.054429 -0.064678"
        rpy="0 0 0" />
      <mass
        value="0.95843" />
      <inertia
        ixx="0.009526"
        ixy="0"
        ixz="0"
        iyy="0.009483"
        iyz="0"
        izz="0.001012" />
    </inertial>
    <visual>
      <origin
        xyz="0 0 0"
        rpy="0 0 0" />
      <geometry>
        <mesh
          filename="package://biped_robot_description/meshes_no_yaw/R_UPPER_LEG.STL" />
      </geometry>
      <material
        name="">
        <color
          rgba="1 1 1 1" />
      </material>
    </visual>
    <collision>
      <origin
        xyz="0 0 0"
        rpy="0 0 0" />
      <geometry>
        <mesh
          filename="package://biped_robot_description/meshes_no_yaw/R_UPPER_LEG.STL" />
      </geometry>
    </collision>
  </link>
  <joint
    name="R_HFE"
    type="revolute">
    <origin
      xyz="0 0 0"
      rpy="0 0 0" />
    <parent
      link="R_SHOULDER" />
    <child
      link="R_UPPER_LEG" />
    <axis
      xyz="0 1 0" />
    <limit
      lower="-1.5"
      upper="1.5"
      effort="20"
      velocity="20" />
  </joint>
  <link
    name="R_LOWER_LEG">
    <inertial>
      <origin
        xyz="-0.000245 0.0242 -0.12419"
        rpy="0 0 0" />
      <mass
        value="0.11574" />
      <inertia
        ixx="0.001579"
        ixy="0"
        ixz="0"
        iyy="0.001579"
        iyz="0"
        izz="2.1E-05" />
    </inertial>
    <visual>
      <origin
        xyz="0 0 0"
        rpy="0 0 0" />
      <geometry>
        <mesh
          filename="package://biped_robot_description/meshes_no_yaw/R_LOWER_LEG.STL" />
      </geometry>
      <material
        name="">
        <color
          rgba="1 1 1 1" />
      </material>
    </visual>
    <collision>
      <origin
        xyz="0 0 0"
        rpy="0 0 0" />
      <geometry>
        <mesh
          filename="package://biped_robot_description/meshes_no_yaw/R_LOWER_LEG.STL" />
      </geometry>
    </collision>
  </link>
  <joint
    name="R_KFE"
    type="revolute">
    <origin
      xyz="0 -0.064178918692559 -0.232529035896276"
      rpy="0 0 0" />
    <parent
      link="R_UPPER_LEG" />
    <child
      link="R_LOWER_LEG" />
    <axis
      xyz="0 1 0" />
    <limit
      lower="-2.2"
      upper="2.2"
      effort="20"
      velocity="20" />
  </joint>
  <link
    name="R_FOOT">
    <inertial>
      <origin
        xyz="0 0 -0.002962"
        rpy="0 0 0" />
      <mass
        value="0.029476" />
      <inertia
        ixx="1E-06"
        ixy="0"
        ixz="0"
        iyy="4.8E-05"
        iyz="0"
        izz="4.8E-05" />
    </inertial>
    <visual>
      <origin
        xyz="0 0 0"
        rpy="0 0 0" />
      <geometry>
        <mesh
          filename="package://biped_robot_description/meshes_no_yaw/R_FOOT.STL" />
      </geometry>
      <material
        name="">
        <color
          rgba="1 1 1 1" />
      </material>
    </visual>
    <collision>
      <origin
        xyz="0 0 0"
        rpy="0 0 0" />
      <geometry>
        <mesh
          filename="package://biped_robot_description/meshes_no_yaw/R_FOOT.STL" />
      </geometry>
    </collision>
  </link>
  <joint
    name="R_ANKLE"
    type="revolute">
    <origin
      xyz="0 0.0245289186685531 -0.326217460949163"
      rpy="0 0 0" />
    <parent
      link="R_LOWER_LEG" />
    <child
      link="R_FOOT" />
    <axis
      xyz="0 1 0" />
    <limit
      lower="-1.6"
      upper="1.6"
      effort="20"
      velocity="20" />
  </joint>

    <link name="R_FOOT_CONTACT"></link>
  <joint
    name="R_FOOT_CONTACT_JOINT"
    type="fixed">
    <origin
      xyz="0.0 0.0173 -0.30326"
      rpy="0 0 0" />
    <parent link="R_LOWER_LEG" />
    <child link="R_FOOT_CONTACT" />
  </joint> 
  <link
    name="L_SHOULDER">
    <inertial>
      <origin
        xyz="-0.00039 -0.022865 0.000966"
        rpy="0 0 0" />
      <mass
        value="0.52963" />
      <inertia
        ixx="0.000368"
        ixy="0"
        ixz="0"
        iyy="0.000691"
        iyz="0"
        izz="0.000491" />
    </inertial>
    <visual>
      <origin
        xyz="0 0 0"
        rpy="0 0 0" />
      <geometry>
        <mesh
          filename="package://biped_robot_description/meshes_no_yaw/L_SHOULDER.STL" />
      </geometry>
      <material
        name="">
        <color
          rgba="1 1 1 1" />
      </material>
    </visual>
    <collision>
      <origin
        xyz="0 0 0"
        rpy="0 0 0" />
      <geometry>
        <mesh
          filename="package://biped_robot_description/meshes_no_yaw/L_SHOULDER.STL" />
      </geometry>
    </collision>
  </link>
  <joint
    name="L_HAA"
    type="revolute">
    <origin
      xyz="0.005 0.07 -0.091"
      rpy="0 0 0" />
    <parent
      link="base_link" />
    <child
      link="L_SHOULDER" />
    <axis
      xyz="1 0 0" />
    <limit
      lower="-0.25"
      upper="0.25"
      effort="20"
      velocity="20" />
  </joint>
  <link
    name="L_UPPER_LEG">
    <inertial>
      <origin
        xyz="2.3E-05 0.054429 -0.064678"
        rpy="0 0 0" />
      <mass
        value="0.958425" />
      <inertia
        ixx="0.009526"
        ixy="0"
        ixz="0"
        iyy="0.009483"
        iyz="1.383E-05"
        izz="0.001012" />
    </inertial>
    <visual>
      <origin
        xyz="0 0 0"
        rpy="0 0 0" />
      <geometry>
        <mesh
          filename="package://biped_robot_description/meshes_no_yaw/L_UPPER_LEG.STL" />
      </geometry>
      <material
        name="">
        <color
          rgba="1 1 1 1" />
      </material>
    </visual>
    <collision>
      <origin
        xyz="0 0 0"
        rpy="0 0 0" />
      <geometry>
        <mesh
          filename="package://biped_robot_description/meshes_no_yaw/L_UPPER_LEG.STL" />
      </geometry>
    </collision>
  </link>
  <joint
    name="L_HFE"
    type="revolute">
    <origin
      xyz="0 0 0"
      rpy="0 0 0" />
    <parent
      link="L_SHOULDER" />
    <child
      link="L_UPPER_LEG" />
    <axis
      xyz="0 1 0" />
    <limit
      lower="-1.5"
      upper="1.5"
      effort="20"
      velocity="20" />
  </joint>
  <link
    name="L_LOWER_LEG">
    <inertial>
      <origin
        xyz="0.000245 -0.019422 -0.122672"
        rpy="0 0 0" />
      <mass
        value="0.115744" />
      <inertia
        ixx="0.001579"
        ixy="0"
        ixz="0"
        iyy="0.001579"
        iyz="0"
        izz="2.1E-05" />
    </inertial>
    <visual>
      <origin
        xyz="0 0 0"
        rpy="0 0 0" />
      <geometry>
        <mesh
          filename="package://biped_robot_description/meshes_no_yaw/L_LOWER_LEG.STL" />
      </geometry>
      <material
        name="">
        <color
          rgba="1 1 1 1" />
      </material>
    </visual>
    <collision>
      <origin
        xyz="0 0 0"
        rpy="0 0 0" />
      <geometry>
        <mesh
          filename="package://biped_robot_description/meshes_no_yaw/L_LOWER_LEG.STL" />
      </geometry>
    </collision>
  </link>
  <joint
    name="L_KFE"
    type="revolute">
    <origin
      xyz="0 0.0594000000000001 -0.234046496851871"
      rpy="0 0 0" />
    <parent
      link="L_UPPER_LEG" />
    <child
      link="L_LOWER_LEG" />
    <axis
      xyz="0 1 0" />
    <limit
      lower="-2.2"
      upper="2.2"
      effort="20"
      velocity="20" />
  </joint>
  <link
    name="L_FOOT">
    <inertial>
      <origin
        xyz="-8.2E-05 0 -0.002961"
        rpy="0 0 0" />
      <mass
        value="0.029476" />
      <inertia
        ixx="1E-06"
        ixy="0"
        ixz="0"
        iyy="4.8E-05"
        iyz="0"
        izz="4.8E-05" />
    </inertial>
    <visual>
      <origin
        xyz="0 0 0"
        rpy="0 0 0" />
      <geometry>
        <mesh
          filename="package://biped_robot_description/meshes_no_yaw/L_FOOT.STL" />
      </geometry>
      <material
        name="">
        <color
          rgba="1 1 1 1" />
      </material>
    </visual>
    <collision>
      <origin
        xyz="0 0 0"
        rpy="0 0 0" />
      <geometry>
        <mesh
          filename="package://biped_robot_description/meshes_no_yaw/L_FOOT.STL" />
      </geometry>
    </collision>
  </link>
  <joint
    name="L_ANKLE"
    type="revolute">
    <origin
      xyz="0 -0.0197500000000014 -0.324699999999999"
      rpy="0 0 0" />
    <parent
      link="L_LOWER_LEG" />
    <child
      link="L_FOOT" />
    <axis
      xyz="0 1 0" />
    <limit
      lower="-1.6"
      upper="1.6"
      effort="20"
      velocity="20" />
  </joint>

     <link name="L_FOOT_CONTACT"></link>
  <joint
    name="L_FOOT_CONTACT_JOINT"
    type="fixed">
    <origin
      xyz="0.0 -0.0173 -0.30326"
      rpy="0 0 0" />
    <parent link="L_LOWER_LEG" />
    <child link="L_FOOT_CONTACT" />
  </joint>
</robot>